You are using pip version 18.0, however version 18.1 is available.
You should consider upgrading via the 'pip install --upgrade pip' command.
You are using pip version 18.0, however version 18.1 is available.
You should consider upgrading via the 'pip install --upgrade pip' command.
You are using pip version 18.0, however version 18.1 is available.
You should consider upgrading via the 'pip install --upgrade pip' command.
Using TensorFlow backend.
/usr/local/lib/python3.5/dist-packages/sklearn/metrics/classification.py:1135: UndefinedMetricWarning: Precision and F-score are ill-defined and being set to 0.0 in labels with no predicted samples.
  'precision', 'predicted', average, warn_for)
Using TensorFlow backend.
/usr/local/lib/python3.5/dist-packages/sklearn/metrics/classification.py:1135: UndefinedMetricWarning: Precision and F-score are ill-defined and being set to 0.0 in labels with no predicted samples.
  'precision', 'predicted', average, warn_for)
Using TensorFlow backend.
/usr/local/lib/python3.5/dist-packages/sklearn/metrics/classification.py:1135: UndefinedMetricWarning: Precision and F-score are ill-defined and being set to 0.0 in labels with no predicted samples.
  'precision', 'predicted', average, warn_for)
Using TensorFlow backend.
Exception ignored in: <bound method BaseSession.__del__ of <tensorflow.python.client.session.Session object at 0x7f9acc6f29b0>>
Traceback (most recent call last):
  File "/usr/local/lib/python3.5/dist-packages/tensorflow/python/client/session.py", line 707, in __del__
TypeError: 'NoneType' object is not callable
Using TensorFlow backend.
/usr/local/lib/python3.5/dist-packages/sklearn/metrics/classification.py:1135: UndefinedMetricWarning: Precision and F-score are ill-defined and being set to 0.0 in labels with no predicted samples.
  'precision', 'predicted', average, warn_for)
Using TensorFlow backend.
/workspace/main.py:347: FutureWarning: Sorting because non-concatenation axis is not aligned. A future version
of pandas will change to not sort by default.

To accept the future behavior, pass 'sort=True'.

To retain the current behavior and silence the warning, pass sort=False

  df = pd.concat(subject_dfs)
Traceback (most recent call last):
  File "/workspace/main.py", line 534, in <module>
    run()
  File "/workspace/main.py", line 462, in run
    val_generator=val_generator)
  File "/workspace/train.py", line 100, in train
    workers=args.nb_workers)
  File "/root/.local/lib/python3.5/site-packages/keras/legacy/interfaces.py", line 91, in wrapper
    return func(*args, **kwargs)
  File "/root/.local/lib/python3.5/site-packages/keras/engine/training.py", line 1418, in fit_generator
    initial_epoch=initial_epoch)
  File "/root/.local/lib/python3.5/site-packages/keras/engine/training_generator.py", line 181, in fit_generator
    generator_output = next(output_generator)
  File "/root/.local/lib/python3.5/site-packages/keras/utils/data_utils.py", line 709, in get
    six.reraise(*sys.exc_info())
  File "/usr/local/lib/python3.5/dist-packages/six.py", line 693, in reraise
    raise value
  File "/root/.local/lib/python3.5/site-packages/keras/utils/data_utils.py", line 685, in get
    inputs = self.queue.get(block=True).get()
  File "/usr/lib/python3.5/multiprocessing/pool.py", line 608, in get
    raise self._value
  File "/usr/lib/python3.5/multiprocessing/pool.py", line 119, in worker
    result = (True, func(*args, **kwds))
  File "/root/.local/lib/python3.5/site-packages/keras/utils/data_utils.py", line 626, in next_sample
    return six.next(_SHARED_SEQUENCES[uid])
  File "/workspace/data_handler.py", line 80, in prepare_generator_2stream
    x = self.get_image(row['Path'])
  File "/workspace/data_handler.py", line 436, in get_image
    im = process_image(path, (self.image_size[0], self.image_size[1], channels))
  File "/workspace/helpers.py", line 15, in process_image
    img = load_img(image_path, target_size=target_shape)
  File "/root/.local/lib/python3.5/site-packages/keras_preprocessing/image.py", line 498, in load_img
    img = pil_image.open(path)
  File "/root/.local/lib/python3.5/site-packages/PIL/Image.py", line 2609, in open
    fp = builtins.open(filename, "rb")
FileNotFoundError: [Errno 2] No such file or directory: '/data/data/jpg_320_180_2fps/horse_1/1_2b/frame_000001.jpg'
